Workbook

Sheet Cronograma
B2: Maria Isabel
B3: Adriana | T3: 6
B4: Airbnb
B5: Booking
B6: Cortesías
B7: No autorizado
B9: 2024 | I9: 2025 | P9: 2026
B10: LUNES | C10: MARTES | D10: MIÉRCOLES | E10: JUEVES | F10: VIERNES | G10: SÁBADO | H10: DOMINGO | I10: LUNES | J10: MARTES | K10: MIÉRCOLES | L10: JUEVES | M10: VIERNES | N10: SÁBADO | O10: DOMINGO | P10: LUNES | Q10: MARTES | R10: MIÉRCOLES | S10: JUEVES | T10: VIERNES | U10: SÁBADO | V10: DOMINGO
B11: ENERO | I11: ENERO | P11: ENERO
B12: 1 | C12: 2 | D12: 3 | E12: 4 | F12: 5 | G12: 6 | H12: 7 | I12: 30 | J12: 31 | K12: 1 | L12: 2 | M12: 3 | N12: 4 | O12: 5 | P12: 29 | Q12: 30 | R12: 31 | S12: 1 | T12: 2 | U12: 3 | V12: 4
J13: Diego Quintero | N13: Claudia Cifuentes | P13: Maritza Mosquera Airbnb | U13: Nicolay Gil Airbnb
B14: 8 | C14: 9 | D14: 10 | E14: 11 | F14: 12 | G14: 13 | H14: 14 | I14: 6 | J14: 7 | K14: 8 | L14: 9 | M14: 10 | N14: 11 | O14: 12 | P14: 5 | Q14: 6 | R14: 7 | S14: 8 | T14: 9 | U14: 10 | V14: 11
I15: Claudia Cifuentes | N15: Marly Andrea Díaz | Q15: Santiago Benavides
B16: 15 | C16: 16 | D16: 17 | E16: 18 | F16: 19 | G16: 20 | H16: 21 | I16: 13 | J16: 14 | K16: 15 | L16: 16 | M16: 17 | N16: 18 | O16: 19 | P16: 12 | Q16: 13 | R16: 14 | S16: 15 | T16: 16 | U16: 17 | V16: 18
J17: COR Alejandra Agudelo | N17: Catherine Tabares Airbnb | P17: Santiago | U17: Andrés Santiago Airbnb
B18: 22 | C18: 23 | D18: 24 | E18: 25 | F18: 26 | G18: 27 | H18: 28 | I18: 20 | J18: 21 | K18: 22 | L18: 23 | M18: 24 | N18: 25 | O18: 26 | P18: 19 | Q18: 20 | R18: 21 | S18: 22 | T18: 23 | U18: 24 | V18: 25
N19: Hernando Díaz Airbnb | P19: COR Alejandra Agudelo | U19: Yaneth Rodríguez
B20: 29 | C20: 30 | D20: 31 | E20: 1 | F20: 2 | G20: 3 | H20: 4 | I20: 27 | J20: 28 | K20: 29 | L20: 30 | M20: 31 | N20: 1 | O20: 2 | P20: 26 | Q20: 27 | R20: 28 | S20: 29 | T20: 30 | U20: 31 | V20: 1
N21: Julián Betancourth | U21: Natalia Acevedo
B22: FEBRERO | I22: FEBRERO | P22: FEBRERO
B23: 5 | C23: 6 | D23: 7 | E23: 8 | F23: 9 | G23: 10 | H23: 11 | I23: 3 | J23: 4 | K23: 5 | L23: 6 | M23: 7 | N23: 8 | O23: 9 | P23: 2 | Q23: 3 | R23: 4 | S23: 5 | T23: 6 | U23: 7 | V23: 8
N24: Valentina Tabares Airbnb | U24: Luceyda Londoño
B25: 12 | C25: 13 | D25: 14 | E25: 15 | F25: 16 | G25: 17 | H25: 18 | I25: 10 | J25: 11 | K25: 12 | L25: 13 | M25: 14 | N25: 15 | O25: 16 | P25: 9 | Q25: 10 | R25: 11 | S25: 12 | T25: 13 | U25: 14 | V25: 15
N26: Angela Sierra | U26: Andrea Grisales Airbnb
B27: 19 | C27: 20 | D27: 21 | E27: 22 | F27: 23 | G27: 24 | H27: 25 | I27: 17 | J27: 18 | K27: 19 | L27: 20 | M27: 21 | N27: 22 | O27: 23 | P27: 16 | Q27: 17 | R27: 18 | S27: 19 | T27: 20 | U27: 21 | V27: 22
N28: Maria Camila Airbnb | S28: Walther Ivan Sanchez Airbnb | V28: William Brion
B29: 26 | C29: 27 | D29: 28 | E29: 29 | F29: 1 | G29: 2 | H29: 3 | I29: 24 | J29: 25 | K29: 26 | L29: 27 | M29: 28 | N29: 1 | O29: 2 | P29: 23 | Q29: 24 | R29: 25 | S29: 26 | T29: 27 | U29: 28 | V29: 1
N30: Paola Laguna | U30: Paula Andrea Ríos
B31: MARZO | I31: MARZO | P31: MARZO
B32: 4 | C32: 5 | D32: 6 | E32: 7 | F32: 8 | G32: 9 | H32: 10 | I32: 3 | J32: 4 | K32: 5 | L32: 6 | M32: 7 | N32: 8 | O32: 9 | P32: 2 | Q32: 3 | R32: 4 | S32: 5 | T32: 6 | U32: 7 | V32: 8
U33: Julián David Muñoz Airbnb
B34: 11 | C34: 12 | D34: 13 | E34: 14 | F34: 15 | G34: 16 | H34: 17 | I34: 10 | J34: 11 | K34: 12 | L34: 13 | M34: 14 | N34: 15 | O34: 16 | P34: 9 | Q34: 10 | R34: 11 | S34: 12 | T34: 13 | U34: 14 | V34: 15
N35: Adolfo Bermudez
B36: 18 | C36: 19 | D36: 20 | E36: 21 | F36: 22 | G36: 23 | H36: 24 | I36: 17 | J36: 18 | K36: 19 | L36: 20 | M36: 21 | N36: 22 | O36: 23 | P36: 16 | Q36: 17 | R36: 18 | S36: 19 | T36: 20 | U36: 21 | V36: 22
N37: Stephanie Gasca Airbnb | U37: Luceyda Londoño
B38: 25 | C38: 26 | D38: 27 | E38: 28 | F38: 29 | G38: 30 | H38: 31 | I38: 24 | J38: 25 | K38: 26 | L38: 27 | M38: 28 | N38: 29 | O38: 30 | P38: 23 | Q38: 24 | R38: 25 | S38: 26 | T38: 27 | U38: 28 | V38: 29
I39: Stephanie Airbnb | N39: Camilo Lucero Airbnb | P39: Santiago
B40: ABRIL | I40: ABRIL | P40: ABRIL
B41: 1 | C41: 2 | D41: 3 | E41: 4 | F41: 5 | G41: 6 | H41: 7 | I41: 31 | J41: 1 | K41: 2 | L41: 3 | M41: 4 | N41: 5 | O41: 6 | P41: 30 | Q41: 31 | R41: 1 | S41: 2 | T41: 3 | U41: 4 | V41: 5
B43: 8 | C43: 9 | D43: 10 | E43: 11 | F43: 12 | G43: 13 | H43: 14 | I43: 7 | J43: 8 | K43: 9 | L43: 10 | M43: 11 | N43: 12 | O43: 13 | P43: 6 | Q43: 7 | R43: 8 | S43: 9 | T43: 10 | U43: 11 | V43: 12
...

Sheet ESTADO DE RESULTADO
A1: Estado de resultado integral 2024
A2: Código cuenta contable | B2: Nombre cuenta contable | C2: ENERO | D2: FEBRERO | E2: MARZO | F2: ABRIL | G2: MAYO | H2: JUNIO | I2: JULIO | J2: AGOSTO | K2: SEPTIEMBRE | L2: OCTUBRE | M2: NOVIEMBRE | N2: DICIEMBRE | O2: ACUMULADO
B3: Ingresos por alquileres | K3: =+'Ingresos _ Egresos 2024'!E10 -> 3450000 | L3: =+'Ingresos _ Egresos 2024'!E26 -> 6150000 | M3: =+'Ingresos _ Egresos 2024'!E41 -> 4912598 | N3: =+'Ingresos _ Egresos 2024'!E55 -> 6099704.7 | O3: =SUM(K3:N3) -> 20612303
B4: Utilidad acumulada del periodo anterior | K4: 0 | L4: 0 | M4: 0 | N4: 0 | O4: =SUM(K4:N4) -> 0
B5: Egresos | K5: =+'Ingresos _ Egresos 2024'!K10 -> 3403276.4 | L5: =+'Ingresos _ Egresos 2024'!K26 -> 5126730.1 | M5: =+'Ingresos _ Egresos 2024'!K41 -> 4892520.7 | N5: =+'Ingresos _ Egresos 2024'!K55 -> 6912673.1 | O5: =SUM(K5:N5) -> 20335200
B6: Comisiones | K6: 140000 | L6: =960000+560000+180000 -> 1700000 | N6: 600000 | O6: =SUM(K6:N6) -> 2440000
B7: Nómina Jairo | K7: =700000+700000 -> 1400000 | L7: =700000+700000 -> 1400000 | M7: =700000+700000 -> 1400000 | N7: =700000+700000+2968000 -> 4368000 | O7: =SUM(K7:N7) -> 8568000
B8: Nómina Omaira | L8: =400000+400000 -> 800000 | M8: 400000 | N8: 400000 | O8: =SUM(K8:N8) -> 1600000
B9: Energía | K9: 1541700 | M9: 894240 | O9: =SUM(K9:N9) -> 2435940
B10: Internet | K10: =103000+51500 -> 154500 | L10: 51500 | M10: 51500 | N10: 51500 | O10: =SUM(K10:N10) -> 309000
B11: Agua | O11: =SUM(K11:N11) -> 0
B12: Gas | M12: 330000 | N12: 338000 | O12: =SUM(K12:N12) -> 668000
B13: Comida perros | K13: 120000 | O13: =SUM(K13:N13) -> 120000
B14: Predial 2024 | M14: 648810 | O14: =SUM(K14:N14) -> 648810
B15: Materiales para guadañar | L15: 150000 | M15: 150000 | O15: =SUM(K15:N15) -> 300000
B16: Quimicos Piscina | L16: 216702 | N16: 316515 | O16: =SUM(K16:N16) -> 533217
B17: Productos aseo | M17: 50000 | O17: =SUM(K17:N17) -> 50000
B18: Mantenimientos generales | L18: =170000+600000 -> 770000 | M18: 400000 | N18: 350000 | O18: =SUM(K18:N18) -> 1520000
B19: Avalúo | M19: 500000 | N19: 450000 | O19: =SUM(K19:N19) -> 950000
B20: Documentos | M20: 20900 | O20: =SUM(K20:N20) -> 20900
B21: Gastos bancarios | K21: =+'Ingresos _ Egresos 2024'!K9 -> 47076.43 | L21: =+'Ingresos _ Egresos 2024'!K25 -> 38528.12 | M21: =+'Ingresos _ Egresos 2024'!K40 -> 47070.66 | N21: =+'Ingresos _ Egresos 2024'!K54 -> 38658.12 | O21: =SUM(K21:N21) -> 171333.33
B22: Utilidad(+)/Pérdida del ejercicio(-) | K22: =+K3-K5 -> 46723.57 | L22: =+L3-L5 -> 1023269.9 | M22: =+M3-M5 -> 20077.34 | N22: =+N3-N5 -> -812968.45 | O22: =SUM(K22:N22) -> 277102.34
A25: Estado de resultado integral 2025
A26: Código cuenta contable | B26: Nombre cuenta contable | C26: ENERO | D26: FEBRERO | E26: MARZO | F26: ABRIL | G26: MAYO | H26: JUNIO | I26: JULIO | J26: AGOSTO | K26: SEPTIEMBRE | L26: OCTUBRE | M26: NOVIEMBRE | N26: DICIEMBRE | O26: ACUMULADO
B27: Ingresos por alquileres | C27: =+'Ingresos_Egresos 2025'!E10 -> 2595458 | D27: =+'Ingresos_Egresos 2025'!E23 -> 3353136 | E27: =+'Ingresos_Egresos 2025'!E39 -> 4845556 | F27: =+'Ingresos_Egresos 2025'!E56 -> 5525117 | G27: =+'Ingresos_Egresos 2025'!E69 -> 6068360 | H27: =+'Ingresos_Egresos 2025'!E89 -> 7846087 | I27: =+'Ingresos_Egresos 2025'!E112 -> 2972621 | J27: =+'Ingresos_Egresos 2025'!E128 -> 8291225 | K27: =+'Ingresos_Egresos 2025'!E148 -> 5371597 | L27: =+'Ingresos_Egresos 2025'!E162 -> 2275000 | M27: =+'Ingresos_Egresos 2025'!E183 -> 2073165 | N27: =+'Ingresos_Egresos 2025'!E202 -> 8665973 | O27: =SUM(C27:N27) -> 59883295
B28: Utilidad acumulada del periodo anterior | C28: =+O22 -> 277102.34 | O28: =SUM(C28:N28) -> 277102.34
B29: Egresos | C29: =+'Ingresos_Egresos 2025'!K10 -> 2548956.2 | D29: =+'Ingresos_Egresos 2025'!K23 -> 4308663.9 | E29: =+'Ingresos_Egresos 2025'!K39 -> 3650057.8 | F29: =+'Ingresos_Egresos 2025'!K56 -> 7473007.9 | G29: =+'Ingresos_Egresos 2025'!K69 -> 4282672.5 | H29: =+'Ingresos_Egresos 2025'!K89 -> 5830790.7 | I29: =+'Ingresos_Egresos 2025'!K112 -> 9270014.5 | J29: =+'Ingresos_Egresos 2025'!K128 -> 2846461.1 | K29: =+'Ingresos_Egresos 2025'!K148 -> 7744737.6 | L29: =+'Ingresos_Egresos 2025'!K162 -> 2604829 | M29: =+'Ingresos_Egresos 2025'!K183 -> 3871154 | N29: =+'Ingresos_Egresos 2025'!K202 -> 5266594.1 | O29: =SUM(C29:N29) -> 59697939
B30: Comisiones | C30: 180000 | D30: 140000 | E30: 180000 | F30: 900000 | H30: 380000 | I30: =576560+190000+180000 -> 946560 | J30: 180000 | K30: =180000+180000+380000+380000+180000 -> 1300000 | L30: 180000 | M30: =380000+180000 -> 560000 | O30: =SUM(C30:N30) -> 4946560
B31: Nómina Jairo | C31: =750000+750000 -> 1500000 | D31: =750000+750000 -> 1500000 | E31: =750000+750000 -> 1500000 | F31: =750000+750000 -> 1500000 | G31: =750000+750000 -> 1500000 | H31: =1500000+750000 -> 2250000 | I31: =750000+750000 -> 1500000 | J31: =750000+750000 -> 1500000 | K31: =750000+750000+2163750 -> 3663750 | L31: =711750+711750 -> 1423500 | M31: =711750+711750 -> 1423500 | N31: =711750+711750+711750 -> 2135250 | O31: =SUM(C31:N31) -> 21396000
B32: Nómina Omaira | C32: 400000 | D32: 400000 | E32: 400000 | F32: 400000 | G32: 500000 | H32: =200000+400000 -> 600000 | I32: 500000 | J32: 500000 | K32: 500000 | L32: 427050 | M32: 474500 | N32: 921950 | O32: =SUM(C32:N32) -> 6023500
B33: Energía | D33: 1031790 | F33: 755920 | H33: =945650 -> 945650 | I33: 789700 | K33: 647390 | N33: 607800 | O33: =SUM(C33:N33) -> 4778250
B34: Internet | C34: 51500 | D34: 51500 | E34: 51500 | F34: 51500 | G34: 51500 | H34: 51500 | I34: 51500 | J34: 51500 | K34: 51500 | L34: 51500 | M34: 51500 | N34: 51500 | O34: =SUM(C34:N34) -> 618000
B35: Agua | H35: =87400+234800 -> 322200 | K35: 87400 | O35: =SUM(C35:N35) -> 409600
B36: Gas | E36: 102000 | G36: 230000 | H36: =98000+210000 -> 308000 | J36: 305000 | L36: 210000 | M36: 95000 | N36: 210000 | O36: =SUM(C36:N36) -> 1460000
B37: Comida perros | O37: =SUM(C37:N37) -> 0
B38: Predial 2025 | E38: 353364 | O38: =SUM(C38:N38) -> 353364
B39: Materiales para guadañar | C39: 112900 | F39: =+'Ingresos_Egresos 2025'!K43+'Ingresos_Egresos 2025'!K44+'Ingresos_Egresos 2025'!K45 -> 158100 | G39: 150000 | H39: 150000 | I39: 150000 | J39: 150000 | L39: 168503 | M39: =81467+150000 -> 231467 | N39: 150000 | O39: =SUM(C39:N39) -> 1420970
B40: Quimicos Piscina | D40: =+'Ingresos_Egresos 2025'!K14 -> 367817 | G40: 518829 | I40: 447617 | K40: 519519 | N40: 619611 | O40: =SUM(C40:N40) -> 2473393
B41: Productos aseo | C41: =158750+107150 -> 265900 | F41: 80000 | I41: =204700+50000 -> 254700 | M41: =121000+163000 -> 284000 | O41: =SUM(C41:N41) -> 884600
B42: Mantenimientos generales | D42: =591003+187900 -> 778903 | F42: =+'Ingresos_Egresos 2025'!K48+'Ingresos_Egresos 2025'!K51+'Ingresos_Egresos 2025'!K42 -> 3597500 | G42: =1272200+12800 -> 1285000 | H42: =400000+160000+50000+107000+76500 -> 793500 | I42: =300000+1000000+700000+100000+1000000+1000000+500000 -> 4600000 | J42: 130000 | K42: =224800+719200 -> 944000 | L42: 100000 | N42: =50000+80000 -> 130000 | O42: =SUM(C42:N42) -> 12358903
...

Sheet Ingresos_Egresos 2026
B2: INGRESOS | C2: FECHA | D2: CONCEPTO | E2: ABONO | F2: SALDO | H2: EGRESOS | I2: FECHA | J2: CONCEPTO | K2: VALOR | M2: UTILIDAD
B3: ENERO | C3: 46024 | D3: Alquiler Santiago Benavides 6 al 12 enero | E3: 2000000 | H3: ENERO | I3: 46024 | J3: Pago Contribución Parafiscal- FONTUR 2025 | K3: 22000 | M3: =+E32-K32 -> -1328445.6
C4: 46027 | D4: Airbnb Alquiler Nicolay Gil 3 - 4 enero | E4: 828315 | I4: 46024 | J4: Seguridad social diciembre | K4: 391220
C5: 46030 | D5: Alquiler Santiago Benavides 6 al 12 enero | E5: 1800000 | I5: 46024 | J5: Pago Agua septiembre - octubre | K5: 87400
C6: 46030 | D6: Alquiler Santiago Benavides 6 al 12 enero deposito | E6: 200000 | I6: 46024 | J6: Pago Agua noviembre - diciembre | K6: 87400
C7: 46034 | D7: Alquiler Yaneth Rodríguez 24 al 25 enero | E7: 475000 | I7: 46024 | J7: Comisión Alquiler Santiago Benavides 6 al 12 enero | K7: =3800000*0.2 -> 760000
C8: 46035 | D8: Alquiler Santiago Benavides 6 al 12 enero deposito | E8: -200000 | I8: 46024 | J8: Compra de cobijas y almohadas | K8: 927500
C9: 46037 | D9: Alquiler Natalia Acevedo 31 ene al 1 feb | E9: 475000 | I9: 46027 | J9: Materiales para guadañar | K9: 180000
C10: 46038 | D10: Alquiler Luceyda Londoño 7 al 8 Feb | E10: 1000000 | I10: 46027 | J10: Aseo adicional sábado 3 enero | K10: 100000
C11: 46042 | D11: Airbnb AlquilerAndrés Santiago 17 - 18 enero | E11: 711577 | I11: 46027 | J11: Aseo adicional lunes 5 enero | K11: 100000
C12: 46044 | D12: Alquiler Yaneth Rodríguez 24 al 25 enero | E12: 475000 | I12: 46028 | J12: Productos de aseo | K12: 349200
C13: 46044 | D13: Alquiler Yaneth Rodríguez 24 al 25 enero deposito | E13: 200000 | I13: 46031 | J13: Pipeta de gas para Jacuzzi | K13: 210000
C14: 46048 | D14: Alquiler Yaneth Rodríguez 24 al 25 enero deposito | E14: -200000 | I14: 46032 | J14: Energia | K14: 738970
C15: 46053 | D15: Alquiler Natalia Acevedo 31 ene al 1 feb | E15: =475000+125000 -> 600000 | I15: 46034 | J15: Pago de Cesantias Jairo y Omaira | K15: 569848.22
C16: 46053 | D16: Alquiler Natalia Acevedo 31 ene al 1 feb deposito | E16: 200000 | I16: 46035 | J16: Arreglo lavadora | K16: 170000
I17: 46036 | J17: Materiales arreglo tuberia rio / Compra guaya | K17: 216000
I18: 46037 | J18: Jairo Primera quincena | K18: 875453
I19: 46038 | J19: Mangueras | K19: 299285
I20: 46038 | J20: Comisión Alquiler alquileres 24 y 31 de enero | K20: 380000
I21: 46038 | J21: Pipeta de gas para cocina | K21: 95000
I22: 46043 | J22: Seguridad social enero | K22: 454020
I23: 46042 | J23: Internet | K23: 51500
I24: 46044 | J24: Arreglo eléctrico | K24: 90000
I25: 46044 | J25: Agua enero | K25: 98000
I26: 46045 | J26: Mantenimiento Jacuzzi | K26: 450000
I27: 46052 | J27: Jairo Segunda quincena | K27: 875453
I28: 46052 | J28: Salario Omaira | K28: 758732
... I31: 46053 | J31: Gastos bancarios | K31: 73656.34
D32: TOTAL INGRESO | E32: =SUM(E3:E31) -> 8564892 | J32: TOTAL EGRESOS | K32: =SUM(K3:K31) -> 9893337.6 | N32: =+M3-'ESTADO DE RESULTADO'!C79 -> -462457.92

Sheet Ingresos_Egresos 2025
B1: INGRESOS | C1: FECHA | D1: CONCEPTO | E1: ABONO | F1: SALDO | H1: EGRESOS | I1: FECHA | J1: CONCEPTO | K1: VALOR | M1: UTILIDAD
B2: ENERO | C2: 45659 | D2: Alquiler Marly Andrea 11-12 ene | E2: 450000 | H2: ENERO | I2: 45659 | J2: Comisión Alquiler Marly Andrea 11-12 ene | K2: 180000 | M2: =+E10-K10 -> 46501.75
C3: 45659 | D3: Alquiler Marly Andrea 11-12 ene depósito | E3: 200000 | I3: 45677 | J3: Internet | K3: 51500
C4: 45661 | D4: Alquiler Marly Andrea 11-12 ene depósito | E4: -200000 | I4: 45677 | J4: Productos aseo | K4: 265900
C5: 45669 | D5: Alquiler Marly Andrea 11-12 ene daño silla | E5: 100000 | I5: 45678 | J5: Primera quincena enero Jairo | K5: 750000
C6: 45671 | D6: Alquiler Angela Sierra 15-16 feb | E6: 120000 | I6: 45681 | J6: Reintegro materiales para guadañar | K6: =77900+35000 -> 112900
C7: 45678 | D7: Airbnb Catherine Tabares 18 - 19 ene | E7: 811411 | I7: 45687 | J7: Segunda quincena enero Jairo | K7: 750000
C8: 45684 | D8: Airbnb Hernando Diaz 25 - 26 ene | E8: 764047 | I8: 45688 | J8: Pago enero Omaira López | K8: 400000
C9: 45688 | D9: Alquiler Juián Betancourth 1- 2 feb | E9: 350000 | I9: 45688 | J9: Gastos bancarios | K9: 38656.25
D10: TOTAL INGRESO | E10: =SUM(E2:E9) -> 2595458 | J10: TOTAL EGRESOS | K10: =SUM(K2:K9) -> 2548956.2 | N10: =+M2-'ESTADO DE RESULTADO'!C47 -> -277102.34
B12: INGRESOS | C12: FECHA | D12: CONCEPTO | E12: ABONO | F12: SALDO | H12: EGRESOS | I12: FECHA | J12: CONCEPTO | K12: VALOR | M12: UTILIDAD
B13: FEBRERO | C13: 45689 | D13: Alquiler Juián Betancourth 1- 2 feb | E13: 350000 | H13: FEBRERO | I13: 45689 | J13: Alquiler Juián Betancourth 1- 2 feb comisión | K13: =+(E9+E13)*0.2 -> 140000 | M13: =+E23-K23 -> -955527.87
C14: 45689 | D14: Alquiler Juián Betancourth 1- 2 feb deposito | E14: 200000 | I14: 45694 | J14: Quimicos piscina | K14: 367817
C15: 45690 | D15: Alquiler Juián Betancourth 1- 2 feb deposito | E15: -200000 | I15: 45704 | J15: Primera quincena febrero Jairo | K15: 750000
C16: 45693 | D16: Alquiler Hebert Adolfo Bermudez 15-16 mar | E16: 200000 | I16: 45708 | J16: Internet febrero | K16: 51500
C17: 45698 | D17: Airbnb Valentina Tabares 8-9 feb | E17: 816108 | I17: 45712 | J17: Energía | K17: 1031790
C18: 45702 | D18: Alquiler Angela Sierra 15-16 feb | E18: 145000 | I18: 45716 | J18: Segunda quincena febrero Jairo | K18: 750000
C19: 45708 | D19: Alquiler Paola Laguna 1-2 mar | E19: 400000 | I19: 45716 | J19: Pago febrero Omaira López | K19: 400000
C20: 45712 | D20: Airbnb Maria Camila 22-23 feb | E20: 842028 | I20: 45716 | J20: Materiales arreglo pisicina | K20: 591003
C21: 45715 | D21: Alquiler Paola Laguna 1-2 mar | E21: 400000 | I21: 45716 | J21: Mano de obra mantenimiento pisicina | K21: 187900
C22: 45716 | D22: Alquiler Hebert Adolfo Bermudez 15-16 mar | E22: 200000 | I22: 45716 | J22: Gastos bancarios | K22: 38653.87
D23: TOTAL INGRESO | E23: =SUM(E13:E22) -> 3353136 | J23: TOTAL EGRESOS | K23: =SUM(K13:K22) -> 4308663.9 | N23: =+M13-'ESTADO DE RESULTADO'!D47 -> 0
B25: INGRESOS | C25: FECHA | D25: CONCEPTO | E25: ABONO | F25: SALDO | H25: EGRESOS | I25: FECHA | J25: CONCEPTO | K25: VALOR | M25: UTILIDAD
B26: MARZO | C26: 45726 | D26: Alquiler Jaime Soto 21 al 27 de Abr | E26: 1850000 | H26: MARZO | I26: 45719 | J26: Gastos notariales levantamiento usufructo | K26: 381945 | M26: =+E39-K39 -> 1195498.2
C27: 45730 | D27: Alquiler Hebert Adolfo Bermudez 15-16 mar | E27: 500000 | I27: 45723 | J27: Boleta fiscal levantamiento usufructo | K27: 404700
C28: 45741 | D28: Stephanie Gasca Airbnb 22-24 mar | E28: 1658969 | I28: 45727 | J28: Cancelación en superintendencia de notariado | K28: 51900
C29: 45747 | D29: Camilo Lucero Airbnb 29-30 mar | E29: 836587 | I29: 45727 | J29: Gastos de escritura nueva | K29: 120000
I30: 45730 | J30: Acto de cancelación de omisión | K30: 57300
I31: 45730 | J31: Alquiler Hebert Adolfo Bermudez 15-16 mar comisión | K31: 180000
I32: 45736 | J32: internet marzo | K32: 51500
I33: 45741 | J33: Primera quincena marzo Jairo | K33: 750000
I34: 45741 | J34: Predial 2025 | K34: 353364
I35: 45743 | J35: Pipeta de gas de la cocina | K35: 102000
I36: 45747 | J36: Segunda quincena marzo Jairo | K36: 750000
I37: 45747 | J37: Pago marzo Omaira López | K37: 400000
I38: 45747 | J38: Gastos bancarios | K38: 47348.84
D39: TOTAL INGRESO | E39: =SUM(E26:E37) -> 4845556 | J39: TOTAL EGRESOS | K39: =SUM(K26:K38) -> 3650057.8 | N39: =+M26-'ESTADO DE RESULTADO'!E47 -> 0
B41: INGRESOS | C41: FECHA | D41: CONCEPTO | E41: ABONO | F41: SALDO | H41: EGRESOS | I41: FECHA | J41: CONCEPTO | K41: VALOR | M41: UTILIDAD
B42: ABRIL | C42: 45766 | D42: Alquiler Jaime Soto 21 al 27 de Abr | E42: 2650000 | H42: ABRIL | I42: 45766 | J42: Compra de toallas | K42: 341900 | M42: =+E56-K56 -> -1947890.9
C43: 45766 | D43: Alquiler Jaime Soto 21 al 27 de Abr déposito | E43: 200000 | I43: 45766 | J43: Compra de aceite para guadañar | K43: 63000
...

Sheet Ingresos _ Egresos 2024
B1: INGRESOS | C1: FECHA | D1: CONCEPTO | E1: ABONO | F1: SALDO | H1: EGRESOS | I1: FECHA | J1: CONCEPTO | K1: VALOR | M1: UTILIDAD
B2: SEPTIEMBRE | C2: 45545 | D2: Alquiler Marbel 5-11Oct | E2: 2300000 | H2: SEPTIEMBRE | I2: 45545 | J2: Energía | K2: 1541700 | M2: =+E10-K10 -> 46723.57
C3: 45546 | D3: Alquiler Viviana 14-15 Sep | E3: 700000 | I3: 45546 | J3: Internet Julio - Agosto | K3: =51500*2 -> 103000
C4: 45546 | D4: Alquiler Viviana 14-15 Sep déposito | E4: 200000 | I4: 45546 | J4: Comisión Viviana 14-15 Sep | K4: 140000
C5: 45550 | D5: Alquiler Viviana 14-15 Sep déposito | E5: -200000 | I5: 45549 | J5: Primera quincena septiembre Jairo | K5: 700000
C6: 45555 | D6: Alquiler Diego Quintero 31 - 2 enero | E6: 450000 | I6: 45555 | J6: Internet Septiembre | K6: 51500
C7: 45555 | D7: Alquiler Erly Aragon 21-22 Sep déposito | E7: 200000 | I7: 45561 | J7: Comida Sasha | K7: 120000
C8: 45557 | D8: Alquiler Erly Aragon 21-22 Sep déposito | E8: -200000 | I8: 45565 | J8: Segunda quincena septiembre Jairo | K8: 700000
I9: 45565 | J9: Gastos bancarios | K9: 47076.43
D10: TOTAL INGRESO | E10: =SUM(E2:E9) -> 3450000 | J10: TOTAL EGRESOS | K10: =SUM(K2:K9) -> 3403276.4 | N10: =+M2-'ESTADO DE RESULTADO'!K22 -> 0
B12: INGRESOS | C12: FECHA | D12: CONCEPTO | E12: ABONO | F12: SALDO | H12: EGRESOS | I12: FECHA | J12: CONCEPTO | K12: VALOR | M12: UTILIDAD
B13: OCTUBRE | C13: 45569 | D13: Alquiler Mateo Vasquez 19 - 20 Oct | E13: 450000 | H13: OCTUBRE | I13: 45569 | J13: Pago septiembre Omaira López | K13: 400000 | M13: =+E26-K26 -> 1023269.9
C14: 45569 | D14: Alquiler Marbel 5-11Oct saldo | E14: 2500000 | I14: 45569 | J14: Comisión Marbel 5-11Oct depósito | K14: 960000
C15: 45569 | D15: Alquiler Marbel 5-11Oct depósito | E15: 200000 | I15: 45570 | J15: Quimicos piscina | K15: 216702
C16: 45576 | D16: Alquiler Marbel 5-11Oct depósito | E16: -200000 | I16: 45579 | J16: Materiales para guadañar | K16: 150000
C17: 45582 | D17: Alquiler Mateo Vasquez 19 - 20 Oct | E17: 450000 | I17: 45582 | J17: Primera quincena octubre Jairo | K17: 700000
C18: 45582 | D18: Alquiler Mateo Vasquez 19 - 20 Oct depósito | E18: 200000 | I18: 17 | J18: Comisión Mateo Vasquez 19 - 20 Oct | K18: =900000*0.2 -> 180000
C19: 45589 | D19: Alquiler Julián Laguna 26-27 Oct | E19: 850000 | I19: 45589 | J19: Arreglo uniones agua | K19: 170000
C20: 45590 | D20: Alquiler Valentina Tafur 14-15 Dic | E20: 900000 | I20: 45589 | J20: Internet octubre | K20: 51500
C21: 45590 | D21: Alquiler Mateo Vasquez 19-20 Oct depósito | E21: -200000 | I21: 45589 | J21: Adelanto Rito arreglo malla | K21: 600000
C22: 45591 | D22: Alquiler Andrés Quejada 2-4 Nov | E22: 1000000 | I22: 45591 | J22: Comisión Andrés Quejada y Valentina Tafur | K22: 560000
I23: 45596 | J23: Segunda quincena octubre Jairo | K23: 700000
I24: 45596 | J24: Pago octubre Omaira López | K24: 400000
I25: 45596 | J25: Gastos bancarios | K25: 38528.12
D26: TOTAL INGRESO | E26: =SUM(E13:E25) -> 6150000 | J26: TOTAL EGRESOS | K26: =SUM(K13:K25) -> 5126730.1 | N26: =+M13-'ESTADO DE RESULTADO'!L22 -> 0
B28: INGRESOS | C28: FECHA | D28: CONCEPTO | E28: ABONO | F28: SALDO | H28: EGRESOS | I28: FECHA | J28: CONCEPTO | K28: VALOR | M28: UTILIDAD
B29: NOVIEMBRE | C29: 45598 | D29: Alquiler Andrés Quejada 2-4 Nov | E29: 900000 | H29: NOVIEMBRE | I29: 45600 | J29: Saldo Rito arreglo malla | K29: 400000 | M29: =+E41-K41 -> 20077.34
C30: 45598 | D30: Alquiler Andrés Quejada 2-4 Nov depósito | E30: 200000 | I30: 45601 | J30: Predial 2024 | K30: 648810
C31: 45610 | D31: Alquiler Marly Andrea 11-12 ene | E31: 450000 | I31: 45611 | J31: Primera quincena noviembre Jairo | K31: 700000
C32: 45613 | D32: Alquiler Francia Navia 24-26 Dic | E32: 700000 | I32: 45614 | J32: Energía | K32: 894240
C33: 45614 | D33: Alquiler Francia Navia 24-26 Dic | E33: 600000 | I33: 45616 | J33: Materiales para guadañar y PH | K33: 200000
C34: 45618 | D34: Airbnb Evelyn 10 - 11 nov | E34: 776788 | I34: 45618 | J34: Internet noviembre | K34: 51500
C35: 45621 | D35: Paola Osorio Airbnb 22 - 23 nov | E35: 810810 | I35: 45623 | J35: Pipetas de gas 100 y 40 | K35: 330000
C36: 45621 | D36: Alquiler Angela Sierra 15-16 feb | E36: 475000 | I36: 45623 | J36: Avalúo Abono 50% | K36: 500000
I37: 45623 | J37: Certificado de tradición | K37: 20900
I38: 45625 | J38: Segundo quincena noviembre Jairo | K38: 700000
I39: 45625 | J39: Pago noviembre Omaira López | K39: 400000
I40: 45626 | J40: Gastos bancarios | K40: 47070.66
D41: TOTAL INGRESO | E41: =SUM(E29:E40) -> 4912598 | J41: TOTAL EGRESOS | K41: =SUM(K29:K40) -> 4892520.7 | N41: =+M29-'ESTADO DE RESULTADO'!M22 -> 0
B43: INGRESOS | C43: FECHA | D43: CONCEPTO | E43: ABONO | F43: SALDO | H43: EGRESOS | I43: FECHA | J43: CONCEPTO | K43: VALOR | M43: UTILIDAD
...
